Workbook
Name Slicer_Duration_Bucket: #N/A
Name Slicer_Representative: #N/A
Name Slicer_Representative1: #N/A
Name Slicer_Representative2: #N/A

Sheet Pivots
C1: Pivot Tables in Excel
C5: Analysis Themes: | E5: Concepts introduced:
C6: 1 | D6: How many calls we are getting by customer? | E6: Pivoting data
C7: 2 | D7: How satisfied are our customers? | E7: Chaging calculation mode
C8: 3 | D8: Who are our top 10 customers? | E8: Filters
C9: 4 | D9: Top 10 customers for a specific representative? | E9: Report filters / slicers
C10: 5 | D10: Call duration analysis | E10: Grouping / bucketing
C11: 6 | D11: How busy is our call centre in 2023? | E11: Trends / pivot chart
C12: 7 | D12: YTD Sales Analysis | E12: Value settings
C13: 8 | D13: Which days of week are the busiest? | E13: Conditional formatting
C14: 9 | D14: Is there a link between call duration and satisfaction rating? | E14: Adding columns, refresh, scatter graph
C15: 10 | D15: Should we hire extra people in any specific months? | E15: Conditional formatting
C17: H1 | D17: Time wasters: Which customers call most but buy least?
C18: H2 | D18: Rep training: Which rep(s) could use satisfaction training program?

Sheet Report page
T30: =IF(OR('All Calculation'!C60="",'All Calculation'!C60=0),"",'All Calculation'!C60) -> Row Labels | U30: =IF(OR('All Calculation'!D60="",'All Calculation'!D60=0),"",'All Calculation'!D60) -> R01 | V30: =IF(OR('All Calculation'!E60="",'All Calculation'!E60=0),"",'All Calculation'!E60) -> R02 | W30: =IF(OR('All Calculation'!F60="",'All Calculation'!F60=0),"",'All Calculation'!F60) -> R03 | X30: =IF(OR('All Calculation'!G60="",'All Calculation'!G60=0),"",'All Calculation'!G60) -> R04 | Y30: =IF(OR('All Calculation'!H60="",'All Calculation'!H60=0),"",'All Calculation'!H60) -> R05 | Z30: =IF(OR('All Calculation'!I60="",'All Calculation'!I60=0),"",'All Calculation'!I60) -> Grand Total
T31: =IF(OR('All Calculation'!C61="",'All Calculation'!C61=0),"",'All Calculation'!C61) -> Cincinnati | U31: =IF(OR('All Calculation'!D61="",'All Calculation'!D61=0),"",'All Calculation'!D61) | V31: =IF(OR('All Calculation'!E61="",'All Calculation'!E61=0),"",'All Calculation'!E61) | W31: =IF(OR('All Calculation'!F61="",'All Calculation'!F61=0),"",'All Calculation'!F61) | X31: =IF(OR('All Calculation'!G61="",'All Calculation'!G61=0),"",'All Calculation'!G61) | Y31: =IF(OR('All Calculation'!H61="",'All Calculation'!H61=0),"",'All Calculation'!H61) | Z31: =IF(OR('All Calculation'!I61="",'All Calculation'!I61=0),"",'All Calculation'!I61)
T33: =IF(OR('All Calculation'!C62="",'All Calculation'!C62=0),"",'All Calculation'!C62) -> C0003 | U33: =IF(OR('All Calculation'!D62="",'All Calculation'!D62=0),"",'All Calculation'!D62) -> 891 | W33: =IF(OR('All Calculation'!F62="",'All Calculation'!F62=0),"",'All Calculation'!F62) -> 1282 | X33: =IF(OR('All Calculation'!G62="",'All Calculation'!G62=0),"",'All Calculation'!G62) -> 739 | Y33: =IF(OR('All Calculation'!H62="",'All Calculation'!H62=0),"",'All Calculation'!H62) -> 560 | Z33: =IF(OR('All Calculation'!I62="",'All Calculation'!I62=0),"",'All Calculation'!I62) -> 4804
T34: =IF(OR('All Calculation'!C63="",'All Calculation'!C63=0),"",'All Calculation'!C63) -> C0004 | U34: =IF(OR('All Calculation'!D63="",'All Calculation'!D63=0),"",'All Calculation'!D63) -> 1991 | V34: =IF(OR('All Calculation'!E63="",'All Calculation'!E63=0),"",'All Calculation'!E63) -> 1886 | W34: =IF(OR('All Calculation'!F63="",'All Calculation'!F63=0),"",'All Calculation'!F63) -> 1206 | X34: =IF(OR('All Calculation'!G63="",'All Calculation'!G63=0),"",'All Calculation'!G63) -> 884 | Y34: =IF(OR('All Calculation'!H63="",'All Calculation'!H63=0),"",'All Calculation'!H63) -> 1722 | Z34: =IF(OR('All Calculation'!I63="",'All Calculation'!I63=0),"",'All Calculation'!I63) -> 7689
T35: =IF(OR('All Calculation'!C64="",'All Calculation'!C64=0),"",'All Calculation'!C64) -> C0011 | U35: =IF(OR('All Calculation'!D64="",'All Calculation'!D64=0),"",'All Calculation'!D64) -> 1163 | V35: =IF(OR('All Calculation'!E64="",'All Calculation'!E64=0),"",'All Calculation'!E64) -> 1180 | W35: =IF(OR('All Calculation'!F64="",'All Calculation'!F64=0),"",'All Calculation'!F64) -> 1616 | X35: =IF(OR('All Calculation'!G64="",'All Calculation'!G64=0),"",'All Calculation'!G64) -> 1043 | Y35: =IF(OR('All Calculation'!H64="",'All Calculation'!H64=0),"",'All Calculation'!H64) -> 1747 | Z35: =IF(OR('All Calculation'!I64="",'All Calculation'!I64=0),"",'All Calculation'!I64) -> 6749
T36: =IF(OR('All Calculation'!C65="",'All Calculation'!C65=0),"",'All Calculation'!C65) -> C0012 | U36: =IF(OR('All Calculation'!D65="",'All Calculation'!D65=0),"",'All Calculation'!D65) -> 1438 | V36: =IF(OR('All Calculation'!E65="",'All Calculation'!E65=0),"",'All Calculation'!E65) -> 1616 | W36: =IF(OR('All Calculation'!F65="",'All Calculation'!F65=0),"",'All Calculation'!F65) -> 866 | X36: =IF(OR('All Calculation'!G65="",'All Calculation'!G65=0),"",'All Calculation'!G65) -> 829 | Y36: =IF(OR('All Calculation'!H65="",'All Calculation'!H65=0),"",'All Calculation'!H65) -> 2070 | Z36: =IF(OR('All Calculation'!I65="",'All Calculation'!I65=0),"",'All Calculation'!I65) -> 6819
T37: =IF(OR('All Calculation'!C66="",'All Calculation'!C66=0),"",'All Calculation'!C66) -> Cleveland | U37: =IF(OR('All Calculation'!D66="",'All Calculation'!D66=0),"",'All Calculation'!D66) | V37: =IF(OR('All Calculation'!E66="",'All Calculation'!E66=0),"",'All Calculation'!E66) | W37: =IF(OR('All Calculation'!F66="",'All Calculation'!F66=0),"",'All Calculation'!F66) | X37: =IF(OR('All Calculation'!G66="",'All Calculation'!G66=0),"",'All Calculation'!G66) | Y37: =IF(OR('All Calculation'!H66="",'All Calculation'!H66=0),"",'All Calculation'!H66) | Z37: =IF(OR('All Calculation'!I66="",'All Calculation'!I66=0),"",'All Calculation'!I66)
T38: =IF(OR('All Calculation'!C67="",'All Calculation'!C67=0),"",'All Calculation'!C67) -> C0002 | U38: =IF(OR('All Calculation'!D67="",'All Calculation'!D67=0),"",'All Calculation'!D67) -> 1233 | V38: =IF(OR('All Calculation'!E67="",'All Calculation'!E67=0),"",'All Calculation'!E67) -> 223 | W38: =IF(OR('All Calculation'!F67="",'All Calculation'!F67=0),"",'All Calculation'!F67) -> 1680 | X38: =IF(OR('All Calculation'!G67="",'All Calculation'!G67=0),"",'All Calculation'!G67) -> 990 | Y38: =IF(OR('All Calculation'!H67="",'All Calculation'!H67=0),"",'All Calculation'!H67) -> 1508 | Z38: =IF(OR('All Calculation'!I67="",'All Calculation'!I67=0),"",'All Calculation'!I67) -> 5634
T39: =IF(OR('All Calculation'!C68="",'All Calculation'!C68=0),"",'All Calculation'!C68) -> C0007 | U39: =IF(OR('All Calculation'!D68="",'All Calculation'!D68=0),"",'All Calculation'!D68) -> 1598 | V39: =IF(OR('All Calculation'!E68="",'All Calculation'!E68=0),"",'All Calculation'!E68) -> 1907 | W39: =IF(OR('All Calculation'!F68="",'All Calculation'!F68=0),"",'All Calculation'!F68) -> 869 | X39: =IF(OR('All Calculation'!G68="",'All Calculation'!G68=0),"",'All Calculation'!G68) -> 1426 | Y39: =IF(OR('All Calculation'!H68="",'All Calculation'!H68=0),"",'All Calculation'!H68) -> 1416 | Z39: =IF(OR('All Calculation'!I68="",'All Calculation'!I68=0),"",'All Calculation'!I68) -> 7216
T41: =IF(OR('All Calculation'!C69="",'All Calculation'!C69=0),"",'All Calculation'!C69) -> C0008 | U41: =IF(OR('All Calculation'!D69="",'All Calculation'!D69=0),"",'All Calculation'!D69) -> 900 | V41: =IF(OR('All Calculation'!E69="",'All Calculation'!E69=0),"",'All Calculation'!E69) -> 1016 | W41: =IF(OR('All Calculation'!F69="",'All Calculation'!F69=0),"",'All Calculation'!F69) -> 960 | X41: =IF(OR('All Calculation'!G69="",'All Calculation'!G69=0),"",'All Calculation'!G69) -> 940 | Y41: =IF(OR('All Calculation'!H69="",'All Calculation'!H69=0),"",'All Calculation'!H69) -> 1193 | Z41: =IF(OR('All Calculation'!I69="",'All Calculation'!I69=0),"",'All Calculation'!I69) -> 5009
T42: =IF(OR('All Calculation'!C70="",'All Calculation'!C70=0),"",'All Calculation'!C70) -> C0010 | U42: =IF(OR('All Calculation'!D70="",'All Calculation'!D70=0),"",'All Calculation'!D70) -> 900 | V42: =IF(OR('All Calculation'!E70="",'All Calculation'!E70=0),"",'All Calculation'!E70) -> 1470 | W42: =IF(OR('All Calculation'!F70="",'All Calculation'!F70=0),"",'All Calculation'!F70) -> 1617 | X42: =IF(OR('All Calculation'!G70="",'All Calculation'!G70=0),"",'All Calculation'!G70) -> 1314 | Y42: =IF(OR('All Calculation'!H70="",'All Calculation'!H70=0),"",'All Calculation'!H70) -> 941 | Z42: =IF(OR('All Calculation'!I70="",'All Calculation'!I70=0),"",'All Calculation'!I70) -> 6242
T43: =IF(OR('All Calculation'!C71="",'All Calculation'!C71=0),"",'All Calculation'!C71) -> C0013 | U43: =IF(OR('All Calculation'!D71="",'All Calculation'!D71=0),"",'All Calculation'!D71) -> 1255 | V43: =IF(OR('All Calculation'!E71="",'All Calculation'!E71=0),"",'All Calculation'!E71) -> 516 | W43: =IF(OR('All Calculation'!F71="",'All Calculation'!F71=0),"",'All Calculation'!F71) -> 1874 | X43: =IF(OR('All Calculation'!G71="",'All Calculation'!G71=0),"",'All Calculation'!G71) -> 1863 | Y43: =IF(OR('All Calculation'!H71="",'All Calculation'!H71=0),"",'All Calculation'!H71) -> 1722 | Z43: =IF(OR('All Calculation'!I71="",'All Calculation'!I71=0),"",'All Calculation'!I71) -> 7230
T44: =IF(OR('All Calculation'!C72="",'All Calculation'!C72=0),"",'All Calculation'!C72) -> C0015 | U44: =IF(OR('All Calculation'!D72="",'All Calculation'!D72=0),"",'All Calculation'!D72) -> 1138 | V44: =IF(OR('All Calculation'!E72="",'All Calculation'!E72=0),"",'All Calculation'!E72) -> 1898 | W44: =IF(OR('All Calculation'!F72="",'All Calculation'!F72=0),"",'All Calculation'!F72) -> 1482 | X44: =IF(OR('All Calculation'!G72="",'All Calculation'!G72=0),"",'All Calculation'!G72) -> 846 | Y44: =IF(OR('All Calculation'!H72="",'All Calculation'!H72=0),"",'All Calculation'!H72) -> 1154 | Z44: =IF(OR('All Calculation'!I72="",'All Calculation'!I72=0),"",'All Calculation'!I72) -> 6518
T45: =IF(OR('All Calculation'!C73="",'All Calculation'!C73=0),"",'All Calculation'!C73) -> Columbus | U45: =IF(OR('All Calculation'!D73="",'All Calculation'!D73=0),"",'All Calculation'!D73) | V45: =IF(OR('All Calculation'!E73="",'All Calculation'!E73=0),"",'All Calculation'!E73) | W45: =IF(OR('All Calculation'!F73="",'All Calculation'!F73=0),"",'All Calculation'!F73) | X45: =IF(OR('All Calculation'!G73="",'All Calculation'!G73=0),"",'All Calculation'!G73) | Y45: =IF(OR('All Calculation'!H73="",'All Calculation'!H73=0),"",'All Calculation'!H73) | Z45: =IF(OR('All Calculation'!I73="",'All Calculation'!I73=0),"",'All Calculation'!I73)
T46: =IF(OR('All Calculation'!C74="",'All Calculation'!C74=0),"",'All Calculation'!C74) -> C0001 | U46: =IF(OR('All Calculation'!D74="",'All Calculation'!D74=0),"",'All Calculation'!D74) -> 1655 | V46: =IF(OR('All Calculation'!E74="",'All Calculation'!E74=0),"",'All Calculation'!E74) -> 805 | W46: =IF(OR('All Calculation'!F74="",'All Calculation'!F74=0),"",'All Calculation'!F74) -> 2263 | X46: =IF(OR('All Calculation'!G74="",'All Calculation'!G74=0),"",'All Calculation'!G74) -> 987 | Y46: =IF(OR('All Calculation'!H74="",'All Calculation'!H74=0),"",'All Calculation'!H74) -> 1075 | Z46: =IF(OR('All Calculation'!I74="",'All Calculation'!I74=0),"",'All Calculation'!I74) -> 6785
T47: =IF(OR('All Calculation'!C75="",'All Calculation'!C75=0),"",'All Calculation'!C75) -> C0005 | U47: =IF(OR('All Calculation'!D75="",'All Calculation'!D75=0),"",'All Calculation'!D75) -> 1104 | V47: =IF(OR('All Calculation'!E75="",'All Calculation'!E75=0),"",'All Calculation'!E75) -> 2280 | W47: =IF(OR('All Calculation'!F75="",'All Calculation'!F75=0),"",'All Calculation'!F75) -> 1445 | X47: =IF(OR('All Calculation'!G75="",'All Calculation'!G75=0),"",'All Calculation'!G75) -> 1722 | Y47: =IF(OR('All Calculation'!H75="",'All Calculation'!H75=0),"",'All Calculation'!H75) -> 1196 | Z47: =IF(OR('All Calculation'!I75="",'All Calculation'!I75=0),"",'All Calculation'!I75) -> 7747
T48: =IF(OR('All Calculation'!C76="",'All Calculation'!C76=0),"",'All Calculation'!C76) -> C0006 | U48: =IF(OR('All Calculation'!D76="",'All Calculation'!D76=0),"",'All Calculation'!D76) -> 372 | V48: =IF(OR('All Calculation'!E76="",'All Calculation'!E76=0),"",'All Calculation'!E76) -> 1818 | W48: =IF(OR('All Calculation'!F76="",'All Calculation'!F76=0),"",'All Calculation'!F76) -> 1346 | X48: =IF(OR('All Calculation'!G76="",'All Calculation'!G76=0),"",'All Calculation'!G76) -> 1156 | Y48: =IF(OR('All Calculation'!H76="",'All Calculation'!H76=0),"",'All Calculation'!H76) -> 1484 | Z48: =IF(OR('All Calculation'!I76="",'All Calculation'!I76=0),"",'All Calculation'!I76) -> 6176
T49: =IF(OR('All Calculation'!C77="",'All Calculation'!C77=0),"",'All Calculation'!C77) -> C0009 | U49: =IF(OR('All Calculation'!D77="",'All Calculation'!D77=0),"",'All Calculation'!D77) -> 1415 | V49: =IF(OR('All Calculation'!E77="",'All Calculation'!E77=0),"",'All Calculation'!E77) -> 1271 | W49: =IF(OR('All Calculation'!F77="",'All Calculation'!F77=0),"",'All Calculation'!F77) -> 1214 | X49: =IF(OR('All Calculation'!G77="",'All Calculation'!G77=0),"",'All Calculation'!G77) -> 1135 | Y49: =IF(OR('All Calculation'!H77="",'All Calculation'!H77=0),"",'All Calculation'!H77) -> 1566 | Z49: =IF(OR('All Calculation'!I77="",'All Calculation'!I77=0),"",'All Calculation'!I77) -> 6601
T50: =IF(OR('All Calculation'!C78="",'All Calculation'!C78=0),"",'All Calculation'!C78) -> C0014 | U50: =IF(OR('All Calculation'!D78="",'All Calculation'!D78=0),"",'All Calculation'!D78) -> 1362 | V50: =IF(OR('All Calculation'!E78="",'All Calculation'!E78=0),"",'All Calculation'!E78) -> 1363 | W50: =IF(OR('All Calculation'!F78="",'All Calculation'!F78=0),"",'All Calculation'!F78) -> 1152 | X50: =IF(OR('All Calculation'!G78="",'All Calculation'!G78=0),"",'All Calculation'!G78) -> 777 | Y50: =IF(OR('All Calculation'!H78="",'All Calculation'!H78=0),"",'All Calculation'!H78) -> 750 | Z50: =IF(OR('All Calculation'!I78="",'All Calculation'!I78=0),"",'All Calculation'!I78) -> 5404
V52: =IF(OR('All Calculation'!C79="",'All Calculation'!C79=0),"",'All Calculation'!C79) | W52: =IF(OR('All Calculation'!D79="",'All Calculation'!D79=0),"",'All Calculation'!D79) | X52: =IF(OR('All Calculation'!E79="",'All Calculation'!E79=0),"",'All Calculation'!E79) | Y52: =IF(OR('All Calculation'!F79="",'All Calculation'!F79=0),"",'All Calculation'!F79) | Z52: =IF(OR('All Calculation'!G79="",'All Calculation'!G79=0),"",'All Calculation'!G79) | AA52: =IF(OR('All Calculation'!H79="",'All Calculation'!H79=0),"",'All Calculation'!H79) | AB52: =IF(OR('All Calculation'!I79="",'All Calculation'!I79=0),"",'All Calculation'!I79)
D70: =IF(C64="","",C64)

Sheet All Calculation
A1: Total Amount | B1: Call Counts | C1: Total Duration | D1: Avg. Rating | E1: 5* Calls
A2: 96623 | B2: 1000 | C2: 89850 | D2: 3.8854 | E2: 307
A7: Total Amount | B7: Call Counts | C7: Total Duration | D7: Avg. Rating | E7: 5* Calls
A8: 20581 | B8: 218 | C8: 19300 | D8: 3.8706422 | E8: 74
A18: Row Labels | B18: Call Counts | C18: Call Counts2
A19: Jan | B19: 19 | C19: 19
A20: Feb | B20: 10 | C20: 10
A21: Mar | B21: 40 | C21: 40 | G21: Row Labels | H21: Call Counts
A22: Apr | B22: 40 | C22: 40 | G22: Sunday | H22: 28
A23: May | B23: 13 | C23: 13 | G23: Monday | H23: 24
A24: Jun | B24: 12 | C24: 12 | G24: Tuesday | H24: 44
A25: Jul | B25: 9 | C25: 9 | G25: Wednesday | H25: 36
A26: Aug | B26: 13 | C26: 13 | G26: Thursday | H26: 33
A27: Sep | B27: 18 | C27: 18 | G27: Friday | H27: 29
A28: Oct | B28: 21 | C28: 21 | G28: Saturday | H28: 24
A29: Nov | B29: 14 | C29: 14 | G29: Grand Total | H29: 218
A30: Dec | B30: 9 | C30: 9
A31: Grand Total | B31: 218 | C31: 218
H35: selected Rep | I35: =A49 -> R02
E36: for graphs
H37: sel. Calls | I37: sel. Amount
A38: Row Labels | B38: Call Counts | C38: Total Amount | E38: {=A39:C43} -> R01 | F38: 189 | G38: 18415 | H38: =IF(E38=$I$35,F38,NA()) -> #N/A | I38: =IF(E38=$I$35,G38,NA()) -> #N/A
A39: R01 | B39: 189 | C39: 18415 | E39: R02 | F39: 218 | G39: 20581 | H39: =IF(E39=$I$35,F39,NA()) -> 218 | I39: =IF(E39=$I$35,G39,NA()) -> 20581
A40: R02 | B40: 218 | C40: 20581 | E40: R03 | F40: 207 | G40: 20872 | H40: =IF(E40=$I$35,F40,NA()) -> #N/A | I40: =IF(E40=$I$35,G40,NA()) -> #N/A
A41: R03 | B41: 207 | C41: 20872 | E41: R04 | F41: 186 | G41: 16651 | H41: =IF(E41=$I$35,F41,NA()) -> #N/A | I41: =IF(E41=$I$35,G41,NA()) -> #N/A
A42: R04 | B42: 186 | C42: 16651 | E42: R05 | F42: 200 | G42: 20104 | H42: =IF(E42=$I$35,F42,NA()) -> #N/A | I42: =IF(E42=$I$35,G42,NA()) -> #N/A
A43: R05 | B43: 200 | C43: 20104
A44: Grand Total | B44: 1000 | C44: 96623
D47: Call Counts | E47: Column Labels
A48: Row Labels | D48: Row Labels | E48: Female | F48: Male | G48: Grand Total | J48: Row Labels | K48: Call Counts
A49: R02 | D49: Cincinnati | E49: 144 | F49: 132 | G49: 276 | J49: 1 | K49: 3
D50: Cleveland | E50: 326 | F50: 63 | G50: 389 | J50: 2 | K50: 19
D51: Columbus | E51: 129 | F51: 206 | G51: 335 | J51: 3 | K51: 35
D52: Grand Total | E52: 599 | F52: 401 | G52: 1000 | J52: 4 | K52: 87
J53: 5 | K53: 74
J54: Grand Total | K54: 218
C59: Total Amount | D59: Column Labels
C60: Row Labels | D60: R01 | E60: R02 | F60: R03 | G60: R04 | H60: R05 | I60: Grand Total
C61: Cincinnati
C62: C0003 | D62: 891 | E62: 1332 | F62: 1282 | G62: 739 | H62: 560 | I62: 4804
...

Sheet 1,2,3
A2: How many calls we are getting by customer?
A3: Row Labels | B3: Count of Call number
A4: C0001 | B4: 65 | F4: How satisfied are our customers? | K4: Who are our top 10 customers?
A5: C0002 | B5: 63
A6: C0003 | B6: 50 | F6: Row Labels | G6: Average of Satisfaction Rating | K6: Row Labels | L6: Sum of Purchase Amount
A7: C0004 | B7: 82 | F7: C0001 | G7: 3.8307692 | K7: C0005 | L7: 7747
A8: C0005 | B8: 79 | F8: C0002 | G8: 4.0730159 | K8: C0004 | L8: 7689
A9: C0006 | B9: 62 | F9: C0003 | G9: 4.018 | K9: C0013 | L9: 7230
A10: C0007 | B10: 67 | F10: C0004 | G10: 3.9768293 | K10: C0007 | L10: 7216
A11: C0008 | B11: 59 | F11: C0005 | G11: 3.9797468 | K11: C0012 | L11: 6819
A12: C0009 | B12: 69 | F12: C0006 | G12: 3.7774194 | K12: C0001 | L12: 6785
A13: C0010 | B13: 72 | F13: C0007 | G13: 3.8522388 | K13: C0011 | L13: 6749
A14: C0011 | B14: 74 | F14: C0008 | G14: 3.9016949 | K14: C0009 | L14: 6601
A15: C0012 | B15: 70 | F15: C0009 | G15: 3.626087 | K15: C0015 | L15: 6518
A16: C0013 | B16: 69 | F16: C0010 | G16: 3.8638889 | K16: C0010 | L16: 6242
A17: C0014 | B17: 60 | F17: C0011 | G17: 3.9837838 | K17: Grand Total | L17: 69596
A18: C0015 | B18: 59 | F18: C0012 | G18: 4.13
A19: Grand Total | B19: 1000 | F19: C0013 | G19: 3.7753623
F20: C0014 | G20: 3.61
F21: C0015 | G21: 3.8389831
F22: Grand Total | G22: 3.8854

Sheet 4
A1: Top 10 customers for a specific representative?
A8: Representative | B8: R02
A10: Row Labels | B10: Sum of Purchase Amount
A11: C0001 | B11: 805
A12: C0002 | B12: 223
A13: C0003 | B13: 1332 | I13: Row Labels | J13: Sum of Purchase Amount
A14: C0004 | B14: 1886 | I14: C0001 | J14: 2263
A15: C0005 | B15: 2280 | I15: C0013 | J15: 1874
A16: C0006 | B16: 1818 | I16: C0002 | J16: 1680
A17: C0007 | B17: 1907 | I17: C0010 | J17: 1617
A18: C0008 | B18: 1016 | I18: C0011 | J18: 1616
A19: C0009 | B19: 1271 | I19: C0015 | J19: 1482
A20: C0010 | B20: 1470 | I20: C0005 | J20: 1445
A21: C0011 | B21: 1180 | I21: C0006 | J21: 1346
A22: C0012 | B22: 1616 | I22: C0003 | J22: 1282
A23: C0013 | B23: 516 | I23: C0009 | J23: 1214
A24: C0014 | B24: 1363 | I24: Grand Total | J24: 15819
A25: C0015 | B25: 1898
A26: Grand Total | B26: 20581

Sheet 5
B2: Call duration analysis
B4: we need to create the new column in the table called Duration Bucket : =IFS([@Duration]<10,"Under 10 Mins",[@Duration]<=30,"10 - 30 Mins",[@Duration]<=60,"30 - 60 Mins",[@Duration]<=120,"1 - 2 Hours",TRUE,"More than 2 Hours")
B6: Row Labels | C6: Count of Call number
B7: 1 - 2 Hours | C7: 524
B8: 10 - 30 Mins | C8: 52
B9: 30 - 60 Mins | C9: 179
B10: More than 2 Hours | C10: 237
B11: Under 10 Mins | C11: 8
B12: Grand Total | C12: 1000

Sheet 6,7
B3: How busy is our call centre in 2023?
B8: Row Labels | C8: Count of Call number
B9: Jan | C9: 79
B10: Feb | C10: 66
B11: Mar | C11: 155
B12: Apr | C12: 136
B13: May | C13: 83
B14: Jun | C14: 67
B15: Jul | C15: 64
B16: Aug | C16: 50
B17: Sep | C17: 76
B18: Oct | C18: 114
B19: Nov | C19: 57
B20: Dec | C20: 53
B21: Grand Total | C21: 1000
B33: we can also add the slicer to get details for each Representative by right cliking on the pivot table fields and the representative
B39: 7 . YTD Sales Analysis
B40: YEAR TO DATE
B43: Row Labels | C43: Sum of Purchase Amount
B44: Jan | C44: 7790
B45: Feb | C45: 13912
B46: Mar | C46: 28475
B47: Apr | C47: 42011
B48: May | C48: 50182
B49: Jun | C49: 56075
B50: Jul | C50: 62082
B51: Aug | C51: 67032
B52: Sep | C52: 73721
B53: Oct | C53: 84596
B54: Nov | C54: 91371
B55: Dec | C55: 96623
B56: Grand Total
C70: RUNNING TOTALS WITH FINANCIAL YEAR
C72: Row Labels | D72: Sum of Purchase Amount
C73: 2023
C74: Jan | D74: 7790
C75: Feb | D75: 13912
C76: Mar | D76: 28475
C77: Apr | D77: 42011
C78: May | D78: 50182
...

Sheet 8
B3: Which days of week are the busiest?
B6: Count of Call number | C6: Column Labels
B7: Row Labels | C7: Sunday | D7: Monday | E7: Tuesday | F7: Wednesday | G7: Thursday | H7: Friday | I7: Saturday | J7: Grand Total
B8: R01 | C8: 0.19047619 | D8: 0.15873016 | E8: 0.068783069 | F8: 0.12169312 | G8: 0.12169312 | H8: 0.12698413 | I8: 0.21164021 | J8: 1
B9: R02 | C9: 0.12844037 | D9: 0.11009174 | E9: 0.20183486 | F9: 0.16513761 | G9: 0.15137615 | H9: 0.13302752 | I9: 0.11009174 | J9: 1
B10: R03 | C10: 0.14492754 | D10: 0.16425121 | E10: 0.12560386 | F10: 0.18357488 | G10: 0.13043478 | H10: 0.13043478 | I10: 0.12077295 | J10: 1
B11: R04 | C11: 0.1344086 | D11: 0.12365591 | E11: 0.15053763 | F11: 0.15591398 | G11: 0.096774194 | H11: 0.15591398 | I11: 0.1827957 | J11: 1
B12: R05 | C12: 0.135 | D12: 0.11 | E12: 0.135 | F12: 0.135 | G12: 0.135 | H12: 0.16 | I12: 0.19 | J12: 1
B13: Grand Total | C13: 0.146 | D13: 0.133 | E13: 0.138 | F13: 0.153 | G13: 0.128 | H13: 0.141 | I13: 0.161 | J13: 1

Sheet 9,10
B2: Is there a link between call duration and satisfaction rating?
B5: Count of Call number | C5: Column Labels
B6: Row Labels | C6: 0 | D6: 1 | E6: 2 | F6: 3 | G6: 4 | H6: 5 | I6: Grand Total
B7: Under 10 Mins | F7: 2 | G7: 4 | H7: 2 | I7: 8
B8: 10 - 30 Mins | E8: 4 | F8: 6 | G8: 27 | H8: 15 | I8: 52
B9: 30 - 60 Mins | E9: 13 | F9: 35 | G9: 75 | H9: 56 | I9: 179
B10: 1 - 2 Hours | D10: 5 | E10: 28 | F10: 106 | G10: 225 | H10: 160 | I10: 524
B11: More than 2 Hours | C11: 1 | D11: 3 | E11: 14 | F11: 48 | G11: 97 | H11: 74 | I11: 237
B12: Grand Total | C12: 1 | D12: 8 | E12: 59 | F12: 197 | G12: 428 | H12: 307 | I12: 1000
B16: Should we hire extra people in any specific months?
B18: Count of Call number | C18: Column Labels
B19: Row Labels | C19: Jan | D19: Feb | E19: Mar | F19: Apr | G19: May | H19: Jun | I19: Jul | J19: Aug | K19: Sep | L19: Oct | M19: Nov | N19: Dec | O19: Grand Total
B20: R01 | C20: 16 | D20: 14 | E20: 26 | F20: 29 | G20: 17 | H20: 15 | I20: 15 | J20: 7 | K20: 11 | L20: 24 | M20: 9 | N20: 6 | O20: 189
B21: R02 | C21: 19 | D21: 10 | E21: 40 | F21: 40 | G21: 13 | H21: 12 | I21: 9 | J21: 13 | K21: 18 | L21: 21 | M21: 14 | N21: 9 | O21: 218
B22: R03 | C22: 13 | D22: 13 | E22: 28 | F22: 24 | G22: 23 | H22: 17 | I22: 11 | J22: 11 | K22: 14 | L22: 30 | M22: 14 | N22: 9 | O22: 207
B23: R04 | C23: 10 | D23: 11 | E23: 30 | F23: 23 | G23: 22 | H23: 11 | I23: 17 | J23: 12 | K23: 13 | L23: 15 | M23: 8 | N23: 14 | O23: 186
B24: R05 | C24: 21 | D24: 18 | E24: 31 | F24: 20 | G24: 8 | H24: 12 | I24: 12 | J24: 7 | K24: 20 | L24: 24 | M24: 12 | N24: 15 | O24: 200
B25: Grand Total | C25: 79 | D25: 66 | E25: 155 | F25: 136 | G25: 83 | H25: 67 | I25: 64 | J25: 50 | K25: 76 | L25: 114 | M25: 57 | N25: 53 | O25: 1000
B27: In the above table we came to a decision that in the month of Mar and Apr the Representative R02 need a support so we can hire one person at that time

Sheet hw
B2: Time wasters: Which customers call most but buy least?
B4: Row Labels | C4: Sum of Purchase Amount
B5: C0003 | C5: 964
B6: C0005 | C6: 1000
B7: C0008 | C7: 1081
B8: C0009 | C8: 799
B9: C0014 | C9: 1194
B10: Grand Total | C10: 5038
B22: Rep training: Which rep(s) could use satisfaction training program?
B24: Count of Call number | C24: Column Labels
B25: Row Labels | C25: 0 | D25: 1 | E25: 2 | F25: 3 | G25: 4 | H25: 5 | I25: Grand Total
B26: R01 | D26: 1 | E26: 9 | F26: 31 | G26: 88 | H26: 60 | I26: 189
B27: R02 | D27: 3 | E27: 19 | F27: 35 | G27: 87 | H27: 74 | I27: 218
B28: R03 | C28: 1 | D28: 1 | E28: 11 | F28: 46 | G28: 88 | H28: 60 | I28: 207
B29: R04 | D29: 3 | E29: 10 | F29: 41 | G29: 70 | H29: 62 | I29: 186
B30: R05 | E30: 10 | F30: 44 | G30: 95 | H30: 51 | I30: 200
B31: Grand Total | C31: 1 | D31: 8 | E31: 59 | F31: 197 | G31: 428 | H31: 307 | I31: 1000

Sheet Data
B1: Call Centre Data
J2: IF(MONTH([@[Date of Call]])<6,YEAR([@[Date of Call]]),YEAR([@[Date of Call]])+1)
B3: Call number | C3: Customer ID | D3: Duration | E3: Representative | F3: Date of Call | G3: Purchase Amount | H3: Satisfaction Rating | I3: FINANCIAL YEAR | J3: DAY OF WEEK | K3: Duration Bucket | L3: Rating Rounded | O3: Customer ID | P3: Gedner | Q3: Age | R3: City
B4: Call_7271 | C4: C0003 | D4: 116 | E4: R05 | F4: 44927 | G4: 128 | H4: 4.9 | I4: =IF(MONTH(Calls[[#This Row],[Date of Call]])<6,YEAR(Calls[[#This Row],[Date of Call]]),YEAR(Calls[[#This Row],[Date of Call]])+1) -> 2023 | J4: =TEXT(Calls[[#This Row],[Date of Call]],"DDDD") -> Sunday | K4: {=_xlfn.IFS(Calls[[#This Row],[Duration]]<10,"Under 10 Mins",Calls[[#This Row],[Duration]]<=30,"10 - 30 Mins",Calls[[#This Row],[Duration]]<=60,"30 - 60 Mins",Calls[[#This Row],[Duration]]<=120,"1 - 2 Hours",TRUE,"More than 2 Hours")} -> 1 - 2 Hours | L4: =ROUND(Calls[[#This Row],[Satisfaction Rating]],0) -> 5 | O4: C0001 | P4: Male | Q4: 41 | R4: Columbus
B5: Call_7272 | C5: C0004 | D5: 119 | E5: R05 | F5: 44927 | G5: 135 | H5: 2.9 | I5: =IF(MONTH(Calls[[#This Row],[Date of Call]])<6,YEAR(Calls[[#This Row],[Date of Call]]),YEAR(Calls[[#This Row],[Date of Call]])+1) -> 2023 | J5: =TEXT(Calls[[#This Row],[Date of Call]],"DDDD") -> Sunday | K5: {=_xlfn.IFS(Calls[[#This Row],[Duration]]<10,"Under 10 Mins",Calls[[#This Row],[Duration]]<=30,"10 - 30 Mins",Calls[[#This Row],[Duration]]<=60,"30 - 60 Mins",Calls[[#This Row],[Duration]]<=120,"1 - 2 Hours",TRUE,"More than 2 Hours")} -> 1 - 2 Hours | L5: =ROUND(Calls[[#This Row],[Satisfaction Rating]],0) -> 3 | O5: C0002 | P5: Male | Q5: 31 | R5: Cleveland
B6: Call_7273 | C6: C0005 | D6: 68 | E6: R02 | F6: 44927 | G6: 66 | H6: 4.7 | I6: =IF(MONTH(Calls[[#This Row],[Date of Call]])<6,YEAR(Calls[[#This Row],[Date of Call]]),YEAR(Calls[[#This Row],[Date of Call]])+1) -> 2023 | J6: =TEXT(Calls[[#This Row],[Date of Call]],"DDDD") -> Sunday | K6: {=_xlfn.IFS(Calls[[#This Row],[Duration]]<10,"Under 10 Mins",Calls[[#This Row],[Duration]]<=30,"10 - 30 Mins",Calls[[#This Row],[Duration]]<=60,"30 - 60 Mins",Calls[[#This Row],[Duration]]<=120,"1 - 2 Hours",TRUE,"More than 2 Hours")} -> 1 - 2 Hours | L6: =ROUND(Calls[[#This Row],[Satisfaction Rating]],0) -> 5 | O6: C0003 | P6: Male | Q6: 26 | R6: Cincinnati
B7: Call_7274 | C7: C0014 | D7: 119 | E7: R02 | F7: 44927 | G7: 22 | H7: 2.9 | I7: =IF(MONTH(Calls[[#This Row],[Date of Call]])<6,YEAR(Calls[[#This Row],[Date of Call]]),YEAR(Calls[[#This Row],[Date of Call]])+1) -> 2023 | J7: =TEXT(Calls[[#This Row],[Date of Call]],"DDDD") -> Sunday | K7: {=_xlfn.IFS(Calls[[#This Row],[Duration]]<10,"Under 10 Mins",Calls[[#This Row],[Duration]]<=30,"10 - 30 Mins",Calls[[#This Row],[Duration]]<=60,"30 - 60 Mins",Calls[[#This Row],[Duration]]<=120,"1 - 2 Hours",TRUE,"More than 2 Hours")} -> 1 - 2 Hours | L7: =ROUND(Calls[[#This Row],[Satisfaction Rating]],0) -> 3 | O7: C0004 | P7: Male | Q7: 36 | R7: Cincinnati
B8: Call_7275 | C8: C0011 | D8: 128 | E8: R01 | F8: 44928 | G8: 31 | H8: 2.8 | I8: =IF(MONTH(Calls[[#This Row],[Date of Call]])<6,YEAR(Calls[[#This Row],[Date of Call]]),YEAR(Calls[[#This Row],[Date of Call]])+1) -> 2023 | J8: =TEXT(Calls[[#This Row],[Date of Call]],"DDDD") -> Monday | K8: {=_xlfn.IFS(Calls[[#This Row],[Duration]]<10,"Under 10 Mins",Calls[[#This Row],[Duration]]<=30,"10 - 30 Mins",Calls[[#This Row],[Duration]]<=60,"30 - 60 Mins",Calls[[#This Row],[Duration]]<=120,"1 - 2 Hours",TRUE,"More than 2 Hours")} -> More than 2 Hours | L8: =ROUND(Calls[[#This Row],[Satisfaction Rating]],0) -> 3 | O8: C0005 | P8: Male | Q8: 37 | R8: Columbus
B9: Call_7276 | C9: C0011 | D9: 49 | E9: R02 | F9: 44929 | G9: 135 | H9: 4.8 | I9: =IF(MONTH(Calls[[#This Row],[Date of Call]])<6,YEAR(Calls[[#This Row],[Date of Call]]),YEAR(Calls[[#This Row],[Date of Call]])+1) -> 2023 | J9: =TEXT(Calls[[#This Row],[Date of Call]],"DDDD") -> Tuesday | K9: {=_xlfn.IFS(Calls[[#This Row],[Duration]]<10,"Under 10 Mins",Calls[[#This Row],[Duration]]<=30,"10 - 30 Mins",Calls[[#This Row],[Duration]]<=60,"30 - 60 Mins",Calls[[#This Row],[Duration]]<=120,"1 - 2 Hours",TRUE,"More than 2 Hours")} -> 30 - 60 Mins | L9: =ROUND(Calls[[#This Row],[Satisfaction Rating]],0) -> 5 | O9: C0006 | P9: Male | Q9: 23 | R9: Columbus
B10: Call_7277 | C10: C0007 | D10: 84 | E10: R05 | F10: 44929 | G10: 60 | H10: 4.7 | I10: =IF(MONTH(Calls[[#This Row],[Date of Call]])<6,YEAR(Calls[[#This Row],[Date of Call]]),YEAR(Calls[[#This Row],[Date of Call]])+1) -> 2023 | J10: =TEXT(Calls[[#This Row],[Date of Call]],"DDDD") -> Tuesday | K10: {=_xlfn.IFS(Calls[[#This Row],[Duration]]<10,"Under 10 Mins",Calls[[#This Row],[Duration]]<=30,"10 - 30 Mins",Calls[[#This Row],[Duration]]<=60,"30 - 60 Mins",Calls[[#This Row],[Duration]]<=120,"1 - 2 Hours",TRUE,"More than 2 Hours")} -> 1 - 2 Hours | L10: =ROUND(Calls[[#This Row],[Satisfaction Rating]],0) -> 5 | O10: C0007 | P10: Female | Q10: 22 | R10: Cleveland
B11: Call_7278 | C11: C0003 | D11: 103 | E11: R04 | F11: 44929 | G11: 148 | H11: 4.4 | I11: =IF(MONTH(Calls[[#This Row],[Date of Call]])<6,YEAR(Calls[[#This Row],[Date of Call]]),YEAR(Calls[[#This Row],[Date of Call]])+1) -> 2023 | J11: =TEXT(Calls[[#This Row],[Date of Call]],"DDDD") -> Tuesday | K11: {=_xlfn.IFS(Calls[[#This Row],[Duration]]<10,"Under 10 Mins",Calls[[#This Row],[Duration]]<=30,"10 - 30 Mins",Calls[[#This Row],[Duration]]<=60,"30 - 60 Mins",Calls[[#This Row],[Duration]]<=120,"1 - 2 Hours",TRUE,"More than 2 Hours")} -> 1 - 2 Hours | L11: =ROUND(Calls[[#This Row],[Satisfaction Rating]],0) -> 4 | O11: C0008 | P11: Female | Q11: 42 | R11: Cleveland
B12: Call_7279 | C12: C0005 | D12: 31 | E12: R02 | F12: 44929 | G12: 135 | H12: 3.6 | I12: =IF(MONTH(Calls[[#This Row],[Date of Call]])<6,YEAR(Calls[[#This Row],[Date of Call]]),YEAR(Calls[[#This Row],[Date of Call]])+1) -> 2023 | J12: =TEXT(Calls[[#This Row],[Date of Call]],"DDDD") -> Tuesday | K12: {=_xlfn.IFS(Calls[[#This Row],[Duration]]<10,"Under 10 Mins",Calls[[#This Row],[Duration]]<=30,"10 - 30 Mins",Calls[[#This Row],[Duration]]<=60,"30 - 60 Mins",Calls[[#This Row],[Duration]]<=120,"1 - 2 Hours",TRUE,"More than 2 Hours")} -> 30 - 60 Mins | L12: =ROUND(Calls[[#This Row],[Satisfaction Rating]],0) -> 4 | O12: C0009 | P12: Female | Q12: 25 | R12: Columbus
B13: Call_7280 | C13: C0010 | D13: 44 | E13: R03 | F13: 44929 | G13: 105 | H13: 2.9 | I13: =IF(MONTH(Calls[[#This Row],[Date of Call]])<6,YEAR(Calls[[#This Row],[Date of Call]]),YEAR(Calls[[#This Row],[Date of Call]])+1) -> 2023 | J13: =TEXT(Calls[[#This Row],[Date of Call]],"DDDD") -> Tuesday | K13: {=_xlfn.IFS(Calls[[#This Row],[Duration]]<10,"Under 10 Mins",Calls[[#This Row],[Duration]]<=30,"10 - 30 Mins",Calls[[#This Row],[Duration]]<=60,"30 - 60 Mins",Calls[[#This Row],[Duration]]<=120,"1 - 2 Hours",TRUE,"More than 2 Hours")} -> 30 - 60 Mins | L13: =ROUND(Calls[[#This Row],[Satisfaction Rating]],0) -> 3 | O13: C0010 | P13: Female | Q13: 30 | R13: Cleveland
B14: Call_7281 | C14: C0011 | D14: 102 | E14: R02 | F14: 44929 | G14: 69 | H14: 4.9 | I14: =IF(MONTH(Calls[[#This Row],[Date of Call]])<6,YEAR(Calls[[#This Row],[Date of Call]]),YEAR(Calls[[#This Row],[Date of Call]])+1) -> 2023 | J14: =TEXT(Calls[[#This Row],[Date of Call]],"DDDD") -> Tuesday | K14: {=_xlfn.IFS(Calls[[#This Row],[Duration]]<10,"Under 10 Mins",Calls[[#This Row],[Duration]]<=30,"10 - 30 Mins",Calls[[#This Row],[Duration]]<=60,"30 - 60 Mins",Calls[[#This Row],[Duration]]<=120,"1 - 2 Hours",TRUE,"More than 2 Hours")} -> 1 - 2 Hours | L14: =ROUND(Calls[[#This Row],[Satisfaction Rating]],0) -> 5 | O14: C0011 | P14: Female | Q14: 30 | R14: Cincinnati
B15: Call_7282 | C15: C0013 | D15: 135 | E15: R05 | F15: 44929 | G15: 46 | H15: 3.4 | I15: =IF(MONTH(Calls[[#This Row],[Date of Call]])<6,YEAR(Calls[[#This Row],[Date of Call]]),YEAR(Calls[[#This Row],[Date of Call]])+1) -> 2023 | J15: =TEXT(Calls[[#This Row],[Date of Call]],"DDDD") -> Tuesday | K15: {=_xlfn.IFS(Calls[[#This Row],[Duration]]<10,"Under 10 Mins",Calls[[#This Row],[Duration]]<=30,"10 - 30 Mins",Calls[[#This Row],[Duration]]<=60,"30 - 60 Mins",Calls[[#This Row],[Duration]]<=120,"1 - 2 Hours",TRUE,"More than 2 Hours")} -> More than 2 Hours | L15: =ROUND(Calls[[#This Row],[Satisfaction Rating]],0) -> 3 | O15: C0012 | P15: Female | Q15: 28 | R15: Cincinnati
... B18: Call_7285 | C18: C0013 | D18: 48 | E18: R01 | F18: 44930 | G18: 68 | H18: 4.9 | I18: =IF(MONTH(Calls[[#This Row],[Date of Call]])<6,YEAR(Calls[[#This Row],[Date of Call]]),YEAR(Calls[[#This Row],[Date of Call]])+1) -> 2023 | J18: =TEXT(Calls[[#This Row],[Date of Call]],"DDDD") -> Wednesday | K18: {=_xlfn.IFS(Calls[[#This Row],[Duration]]<10,"Under 10 Mins",Calls[[#This Row],[Duration]]<=30,"10 - 30 Mins",Calls[[#This Row],[Duration]]<=60,"30 - 60 Mins",Calls[[#This Row],[Duration]]<=120,"1 - 2 Hours",TRUE,"More than 2 Hours")} -> 30 - 60 Mins | L18: =ROUND(Calls[[#This Row],[Satisfaction Rating]],0) -> 5 | O18: C0015 | P18: Female | Q18: 43 | R18: Cleveland
B19: Call_7286 | C19: C0010 | D19: 176 | E19: R05 | F19: 44931 | G19: 24 | H19: 4.8 | I19: =IF(MONTH(Calls[[#This Row],[Date of Call]])<6,YEAR(Calls[[#This Row],[Date of Call]]),YEAR(Calls[[#This Row],[Date of Call]])+1) -> 2023 | J19: =TEXT(Calls[[#This Row],[Date of Call]],"DDDD") -> Thursday | K19: {=_xlfn.IFS(Calls[[#This Row],[Duration]]<10,"Under 10 Mins",Calls[[#This Row],[Duration]]<=30,"10 - 30 Mins",Calls[[#This Row],[Duration]]<=60,"30 - 60 Mins",Calls[[#This Row],[Duration]]<=120,"1 - 2 Hours",TRUE,"More than 2 Hours")} -> More than 2 Hours | L19: =ROUND(Calls[[#This Row],[Satisfaction Rating]],0) -> 5
B20: Call_7287 | C20: C0010 | D20: 99 | E20: R01 | F20: 44931 | G20: 195 | H20: 3.9 | I20: =IF(MONTH(Calls[[#This Row],[Date of Call]])<6,YEAR(Calls[[#This Row],[Date of Call]]),YEAR(Calls[[#This Row],[Date of Call]])+1) -> 2023 | J20: =TEXT(Calls[[#This Row],[Date of Call]],"DDDD") -> Thursday | K20: {=_xlfn.IFS(Calls[[#This Row],[Duration]]<10,"Under 10 Mins",Calls[[#This Row],[Duration]]<=30,"10 - 30 Mins",Calls[[#This Row],[Duration]]<=60,"30 - 60 Mins",Calls[[#This Row],[Duration]]<=120,"1 - 2 Hours",TRUE,"More than 2 Hours")} -> 1 - 2 Hours | L20: =ROUND(Calls[[#This Row],[Satisfaction Rating]],0) -> 4
B21: Call_7288 | C21: C0009 | D21: 28 | E21: R03 | F21: 44931 | G21: 28 | H21: 3.8 | I21: =IF(MONTH(Calls[[#This Row],[Date of Call]])<6,YEAR(Calls[[#This Row],[Date of Call]]),YEAR(Calls[[#This Row],[Date of Call]])+1) -> 2023 | J21: =TEXT(Calls[[#This Row],[Date of Call]],"DDDD") -> Thursday | K21: {=_xlfn.IFS(Calls[[#This Row],[Duration]]<10,"Under 10 Mins",Calls[[#This Row],[Duration]]<=30,"10 - 30 Mins",Calls[[#This Row],[Duration]]<=60,"30 - 60 Mins",Calls[[#This Row],[Duration]]<=120,"1 - 2 Hours",TRUE,"More than 2 Hours")} -> 10 - 30 Mins | L21: =ROUND(Calls[[#This Row],[Satisfaction Rating]],0) -> 4
B22: Call_7289 | C22: C0007 | D22: 54 | E22: R02 | F22: 44931 | G22: 170 | H22: 4.3 | I22: =IF(MONTH(Calls[[#This Row],[Date of Call]])<6,YEAR(Calls[[#This Row],[Date of Call]]),YEAR(Calls[[#This Row],[Date of Call]])+1) -> 2023 | J22: =TEXT(Calls[[#This Row],[Date of Call]],"DDDD") -> Thursday | K22: {=_xlfn.IFS(Calls[[#This Row],[Duration]]<10,"Under 10 Mins",Calls[[#This Row],[Duration]]<=30,"10 - 30 Mins",Calls[[#This Row],[Duration]]<=60,"30 - 60 Mins",Calls[[#This Row],[Duration]]<=120,"1 - 2 Hours",TRUE,"More than 2 Hours")} -> 30 - 60 Mins | L22: =ROUND(Calls[[#This Row],[Satisfaction Rating]],0) -> 4
B23: Call_7290 | C23: C0006 | D23: 48 | E23: R05 | F23: 44932 | G23: 30 | H23: 4.4 | I23: =IF(MONTH(Calls[[#This Row],[Date of Call]])<6,YEAR(Calls[[#This Row],[Date of Call]]),YEAR(Calls[[#This Row],[Date of Call]])+1) -> 2023 | J23: =TEXT(Calls[[#This Row],[Date of Call]],"DDDD") -> Friday | K23: {=_xlfn.IFS(Calls[[#This Row],[Duration]]<10,"Under 10 Mins",Calls[[#This Row],[Duration]]<=30,"10 - 30 Mins",Calls[[#This Row],[Duration]]<=60,"30 - 60 Mins",Calls[[#This Row],[Duration]]<=120,"1 - 2 Hours",TRUE,"More than 2 Hours")} -> 30 - 60 Mins | L23: =ROUND(Calls[[#This Row],[Satisfaction Rating]],0) -> 4
B24: Call_7291 | C24: C0004 | D24: 128 | E24: R05 | F24: 44932 | G24: 72 | H24: 5 | I24: =IF(MONTH(Calls[[#This Row],[Date of Call]])<6,YEAR(Calls[[#This Row],[Date of Call]]),YEAR(Calls[[#This Row],[Date of Call]])+1) -> 2023 | J24: =TEXT(Calls[[#This Row],[Date of Call]],"DDDD") -> Friday | K24: {=_xlfn.IFS(Calls[[#This Row],[Duration]]<10,"Under 10 Mins",Calls[[#This Row],[Duration]]<=30,"10 - 30 Mins",Calls[[#This Row],[Duration]]<=60,"30 - 60 Mins",Calls[[#This Row],[Duration]]<=120,"1 - 2 Hours",TRUE,"More than 2 Hours")} -> More than 2 Hours | L24: =ROUND(Calls[[#This Row],[Satisfaction Rating]],0) -> 5
B25: Call_7292 | C25: C0004 | D25: 38 | E25: R04 | F25: 44933 | G25: 92 | H25: 4.9 | I25: =IF(MONTH(Calls[[#This Row],[Date of Call]])<6,YEAR(Calls[[#This Row],[Date of Call]]),YEAR(Calls[[#This Row],[Date of Call]])+1) -> 2023 | J25: =TEXT(Calls[[#This Row],[Date of Call]],"DDDD") -> Saturday | K25: {=_xlfn.IFS(Calls[[#This Row],[Duration]]<10,"Under 10 Mins",Calls[[#This Row],[Duration]]<=30,"10 - 30 Mins",Calls[[#This Row],[Duration]]<=60,"30 - 60 Mins",Calls[[#This Row],[Duration]]<=120,"1 - 2 Hours",TRUE,"More than 2 Hours")} -> 30 - 60 Mins | L25: =ROUND(Calls[[#This Row],[Satisfaction Rating]],0) -> 5
B26: Call_7293 | C26: C0003 | D26: 67 | E26: R04 | F26: 44934 | G26: 165 | H26: 4.5 | I26: =IF(MONTH(Calls[[#This Row],[Date of Call]])<6,YEAR(Calls[[#This Row],[Date of Call]]),YEAR(Calls[[#This Row],[Date of Call]])+1) -> 2023 | J26: =TEXT(Calls[[#This Row],[Date of Call]],"DDDD") -> Sunday | K26: {=_xlfn.IFS(Calls[[#This Row],[Duration]]<10,"Under 10 Mins",Calls[[#This Row],[Duration]]<=30,"10 - 30 Mins",Calls[[#This Row],[Duration]]<=60,"30 - 60 Mins",Calls[[#This Row],[Duration]]<=120,"1 - 2 Hours",TRUE,"More than 2 Hours")} -> 1 - 2 Hours | L26: =ROUND(Calls[[#This Row],[Satisfaction Rating]],0) -> 5
B27: Call_7294 | C27: C0015 | D27: 58 | E27: R02 | F27: 44934 | G27: 140 | H27: 2.1 | I27: =IF(MONTH(Calls[[#This Row],[Date of Call]])<6,YEAR(Calls[[#This Row],[Date of Call]]),YEAR(Calls[[#This Row],[Date of Call]])+1) -> 2023 | J27: =TEXT(Calls[[#This Row],[Date of Call]],"DDDD") -> Sunday | K27: {=_xlfn.IFS(Calls[[#This Row],[Duration]]<10,"Under 10 Mins",Calls[[#This Row],[Duration]]<=30,"10 - 30 Mins",Calls[[#This Row],[Duration]]<=60,"30 - 60 Mins",Calls[[#This Row],[Duration]]<=120,"1 - 2 Hours",TRUE,"More than 2 Hours")} -> 30 - 60 Mins | L27: =ROUND(Calls[[#This Row],[Satisfaction Rating]],0) -> 2
B28: Call_7295 | C28: C0010 | D28: 54 | E28: R01 | F28: 44934 | G28: 111 | H28: 3.3 | I28: =IF(MONTH(Calls[[#This Row],[Date of Call]])<6,YEAR(Calls[[#This Row],[Date of Call]]),YEAR(Calls[[#This Row],[Date of Call]])+1) -> 2023 | J28: =TEXT(Calls[[#This Row],[Date of Call]],"DDDD") -> Sunday | K28: {=_xlfn.IFS(Calls[[#This Row],[Duration]]<10,"Under 10 Mins",Calls[[#This Row],[Duration]]<=30,"10 - 30 Mins",Calls[[#This Row],[Duration]]<=60,"30 - 60 Mins",Calls[[#This Row],[Duration]]<=120,"1 - 2 Hours",TRUE,"More than 2 Hours")} -> 30 - 60 Mins | L28: =ROUND(Calls[[#This Row],[Satisfaction Rating]],0) -> 3
B29: Call_7296 | C29: C0012 | D29: 28 | E29: R05 | F29: 44935 | G29: 63 | H29: 4.1 | I29: =IF(MONTH(Calls[[#This Row],[Date of Call]])<6,YEAR(Calls[[#This Row],[Date of Call]]),YEAR(Calls[[#This Row],[Date of Call]])+1) -> 2023 | J29: =TEXT(Calls[[#This Row],[Date of Call]],"DDDD") -> Monday | K29: {=_xlfn.IFS(Calls[[#This Row],[Duration]]<10,"Under 10 Mins",Calls[[#This Row],[Duration]]<=30,"10 - 30 Mins",Calls[[#This Row],[Duration]]<=60,"30 - 60 Mins",Calls[[#This Row],[Duration]]<=120,"1 - 2 Hours",TRUE,"More than 2 Hours")} -> 10 - 30 Mins | L29: =ROUND(Calls[[#This Row],[Satisfaction Rating]],0) -> 4
B30: Call_7297 | C30: C0002 | D30: 73 | E30: R05 | F30: 44935 | G30: 80 | H30: 4.2 | I30: =IF(MONTH(Calls[[#This Row],[Date of Call]])<6,YEAR(Calls[[#This Row],[Date of Call]]),YEAR(Calls[[#This Row],[Date of Call]])+1) -> 2023 | J30: =TEXT(Calls[[#This Row],[Date of Call]],"DDDD") -> Monday | K30: {=_xlfn.IFS(Calls[[#This Row],[Duration]]<10,"Under 10 Mins",Calls[[#This Row],[Duration]]<=30,"10 - 30 Mins",Calls[[#This Row],[Duration]]<=60,"30 - 60 Mins",Calls[[#This Row],[Duration]]<=120,"1 - 2 Hours",TRUE,"More than 2 Hours")} -> 1 - 2 Hours | L30: =ROUND(Calls[[#This Row],[Satisfaction Rating]],0) -> 4
... B1003: Call_8270 | C1003: C0009 | D1003: 114 | E1003: R01 | F1003: 45291 | G1003: 40 | H1003: 3.9 | I1003: =IF(MONTH(Calls[[#This Row],[Date of Call]])<6,YEAR(Calls[[#This Row],[Date of Call]]),YEAR(Calls[[#This Row],[Date of Call]])+1) -> 2024 | J1003: =TEXT(Calls[[#This Row],[Date of Call]],"DDDD") -> Sunday | K1003: {=_xlfn.IFS(Calls[[#This Row],[Duration]]<10,"Under 10 Mins",Calls[[#This Row],[Duration]]<=30,"10 - 30 Mins",Calls[[#This Row],[Duration]]<=60,"30 - 60 Mins",Calls[[#This Row],[Duration]]<=120,"1 - 2 Hours",TRUE,"More than 2 Hours")} -> 1 - 2 Hours | L1003: =ROUND(Calls[[#This Row],[Satisfaction Rating]],0) -> 4
G1004: =SUBTOTAL(109,Calls[Purchase Amount]) -> 96623
